üöÄ Starting API Service locally...
üèÉ Starting API Service on port 8002...
üìö API documentation available at:
   - Swagger UI: http://localhost:8002/docs
   - ReDoc: http://localhost:8002/redoc
INFO:     Will watch for changes in these directories: ['/home/sjiang/devlocal/jnet-site/services/api-service']
INFO:     Uvicorn running on http://127.0.0.1:8002 (Press CTRL+C to quit)
INFO:     Started reloader process [165239] using StatReload
INFO:     Started server process [165241]
INFO:     Waiting for application startup.
INFO:app.main:Starting API Service in development mode
INFO:     Application startup complete.
WARNING:app.middleware.auth:Invalid API key attempt from 127.0.0.1
INFO:     127.0.0.1:53148 - "GET /api/v1/symbols/list HTTP/1.1" 500 Internal Server Error
ERROR:    Exception in ASGI application
  + Exception Group Traceback (most recent call last):
  |   File "/home/sjiang/devlocal/jnet-site/services/api-service/.venv/lib/python3.11/site-packages/starlette/_utils.py", line 79, in collapse_excgroups
  |     yield
  |   File "/home/sjiang/devlocal/jnet-site/services/api-service/.venv/lib/python3.11/site-packages/starlette/middleware/base.py", line 183, in __call__
  |     async with anyio.create_task_group() as task_group:
  |   File "/home/sjiang/devlocal/jnet-site/services/api-service/.venv/lib/python3.11/site-packages/anyio/_backends/_asyncio.py", line 772, in __aexit__
  |     raise BaseExceptionGroup(
  | ExceptionGroup: unhandled errors in a TaskGroup (1 sub-exception)
  +-+---------------- 1 ----------------
    | Traceback (most recent call last):
    |   File "/home/sjiang/devlocal/jnet-site/services/api-service/.venv/lib/python3.11/site-packages/uvicorn/protocols/http/h11_impl.py", line 403, in run_asgi
    |     result = await app(  # type: ignore[func-returns-value]
    |              ^^^^^^^^^^^^^^^^^^^^^^^^^^^^^^^^^^^^^^^^^^^^^^
    |   File "/home/sjiang/devlocal/jnet-site/services/api-service/.venv/lib/python3.11/site-packages/uvicorn/middleware/proxy_headers.py", line 60, in __call__
    |     return await self.app(scope, receive, send)
    |            ^^^^^^^^^^^^^^^^^^^^^^^^^^^^^^^^^^^^
    |   File "/home/sjiang/devlocal/jnet-site/services/api-service/.venv/lib/python3.11/site-packages/fastapi/applications.py", line 1054, in __call__
    |     await super().__call__(scope, receive, send)
    |   File "/home/sjiang/devlocal/jnet-site/services/api-service/.venv/lib/python3.11/site-packages/starlette/applications.py", line 113, in __call__
    |     await self.middleware_stack(scope, receive, send)
    |   File "/home/sjiang/devlocal/jnet-site/services/api-service/.venv/lib/python3.11/site-packages/starlette/middleware/errors.py", line 186, in __call__
    |     raise exc
    |   File "/home/sjiang/devlocal/jnet-site/services/api-service/.venv/lib/python3.11/site-packages/starlette/middleware/errors.py", line 164, in __call__
    |     await self.app(scope, receive, _send)
    |   File "/home/sjiang/devlocal/jnet-site/services/api-service/.venv/lib/python3.11/site-packages/starlette/middleware/base.py", line 182, in __call__
    |     with recv_stream, send_stream, collapse_excgroups():
    |   File "/home/sjiang/.local/share/uv/python/cpython-3.11.13-linux-x86_64-gnu/lib/python3.11/contextlib.py", line 158, in __exit__
    |     self.gen.throw(typ, value, traceback)
    |   File "/home/sjiang/devlocal/jnet-site/services/api-service/.venv/lib/python3.11/site-packages/starlette/_utils.py", line 85, in collapse_excgroups
    |     raise exc
    |   File "/home/sjiang/devlocal/jnet-site/services/api-service/.venv/lib/python3.11/site-packages/starlette/middleware/base.py", line 184, in __call__
    |     response = await self.dispatch_func(request, call_next)
    |                ^^^^^^^^^^^^^^^^^^^^^^^^^^^^^^^^^^^^^^^^^^^^
    |   File "/home/sjiang/devlocal/jnet-site/services/api-service/app/middleware/auth.py", line 30, in dispatch
    |     raise HTTPException(status_code=401, detail="Invalid API key")
    | fastapi.exceptions.HTTPException: 401: Invalid API key
    +------------------------------------

During handling of the above exception, another exception occurred:

Traceback (most recent call last):
  File "/home/sjiang/devlocal/jnet-site/services/api-service/.venv/lib/python3.11/site-packages/uvicorn/protocols/http/h11_impl.py", line 403, in run_asgi
    result = await app(  # type: ignore[func-returns-value]
             ^^^^^^^^^^^^^^^^^^^^^^^^^^^^^^^^^^^^^^^^^^^^^^
  File "/home/sjiang/devlocal/jnet-site/services/api-service/.venv/lib/python3.11/site-packages/uvicorn/middleware/proxy_headers.py", line 60, in __call__
    return await self.app(scope, receive, send)
           ^^^^^^^^^^^^^^^^^^^^^^^^^^^^^^^^^^^^
  File "/home/sjiang/devlocal/jnet-site/services/api-service/.venv/lib/python3.11/site-packages/fastapi/applications.py", line 1054, in __call__
    await super().__call__(scope, receive, send)
  File "/home/sjiang/devlocal/jnet-site/services/api-service/.venv/lib/python3.11/site-packages/starlette/applications.py", line 113, in __call__
    await self.middleware_stack(scope, receive, send)
  File "/home/sjiang/devlocal/jnet-site/services/api-service/.venv/lib/python3.11/site-packages/starlette/middleware/errors.py", line 186, in __call__
    raise exc
  File "/home/sjiang/devlocal/jnet-site/services/api-service/.venv/lib/python3.11/site-packages/starlette/middleware/errors.py", line 164, in __call__
    await self.app(scope, receive, _send)
  File "/home/sjiang/devlocal/jnet-site/services/api-service/.venv/lib/python3.11/site-packages/starlette/middleware/base.py", line 182, in __call__
    with recv_stream, send_stream, collapse_excgroups():
  File "/home/sjiang/.local/share/uv/python/cpython-3.11.13-linux-x86_64-gnu/lib/python3.11/contextlib.py", line 158, in __exit__
    self.gen.throw(typ, value, traceback)
  File "/home/sjiang/devlocal/jnet-site/services/api-service/.venv/lib/python3.11/site-packages/starlette/_utils.py", line 85, in collapse_excgroups
    raise exc
  File "/home/sjiang/devlocal/jnet-site/services/api-service/.venv/lib/python3.11/site-packages/starlette/middleware/base.py", line 184, in __call__
    response = await self.dispatch_func(request, call_next)
               ^^^^^^^^^^^^^^^^^^^^^^^^^^^^^^^^^^^^^^^^^^^^
  File "/home/sjiang/devlocal/jnet-site/services/api-service/app/middleware/auth.py", line 30, in dispatch
    raise HTTPException(status_code=401, detail="Invalid API key")
fastapi.exceptions.HTTPException: 401: Invalid API key
WARNING:app.middleware.auth:Invalid API key attempt from 127.0.0.1
INFO:     127.0.0.1:48620 - "GET /api/v1/symbols/list HTTP/1.1" 500 Internal Server Error
ERROR:    Exception in ASGI application
  + Exception Group Traceback (most recent call last):
  |   File "/home/sjiang/devlocal/jnet-site/services/api-service/.venv/lib/python3.11/site-packages/starlette/_utils.py", line 79, in collapse_excgroups
  |     yield
  |   File "/home/sjiang/devlocal/jnet-site/services/api-service/.venv/lib/python3.11/site-packages/starlette/middleware/base.py", line 183, in __call__
  |     async with anyio.create_task_group() as task_group:
  |   File "/home/sjiang/devlocal/jnet-site/services/api-service/.venv/lib/python3.11/site-packages/anyio/_backends/_asyncio.py", line 772, in __aexit__
  |     raise BaseExceptionGroup(
  | ExceptionGroup: unhandled errors in a TaskGroup (1 sub-exception)
  +-+---------------- 1 ----------------
    | Traceback (most recent call last):
    |   File "/home/sjiang/devlocal/jnet-site/services/api-service/.venv/lib/python3.11/site-packages/uvicorn/protocols/http/h11_impl.py", line 403, in run_asgi
    |     result = await app(  # type: ignore[func-returns-value]
    |              ^^^^^^^^^^^^^^^^^^^^^^^^^^^^^^^^^^^^^^^^^^^^^^
    |   File "/home/sjiang/devlocal/jnet-site/services/api-service/.venv/lib/python3.11/site-packages/uvicorn/middleware/proxy_headers.py", line 60, in __call__
    |     return await self.app(scope, receive, send)
    |            ^^^^^^^^^^^^^^^^^^^^^^^^^^^^^^^^^^^^
    |   File "/home/sjiang/devlocal/jnet-site/services/api-service/.venv/lib/python3.11/site-packages/fastapi/applications.py", line 1054, in __call__
    |     await super().__call__(scope, receive, send)
    |   File "/home/sjiang/devlocal/jnet-site/services/api-service/.venv/lib/python3.11/site-packages/starlette/applications.py", line 113, in __call__
    |     await self.middleware_stack(scope, receive, send)
    |   File "/home/sjiang/devlocal/jnet-site/services/api-service/.venv/lib/python3.11/site-packages/starlette/middleware/errors.py", line 186, in __call__
    |     raise exc
    |   File "/home/sjiang/devlocal/jnet-site/services/api-service/.venv/lib/python3.11/site-packages/starlette/middleware/errors.py", line 164, in __call__
    |     await self.app(scope, receive, _send)
    |   File "/home/sjiang/devlocal/jnet-site/services/api-service/.venv/lib/python3.11/site-packages/starlette/middleware/base.py", line 182, in __call__
    |     with recv_stream, send_stream, collapse_excgroups():
    |   File "/home/sjiang/.local/share/uv/python/cpython-3.11.13-linux-x86_64-gnu/lib/python3.11/contextlib.py", line 158, in __exit__
    |     self.gen.throw(typ, value, traceback)
    |   File "/home/sjiang/devlocal/jnet-site/services/api-service/.venv/lib/python3.11/site-packages/starlette/_utils.py", line 85, in collapse_excgroups
    |     raise exc
    |   File "/home/sjiang/devlocal/jnet-site/services/api-service/.venv/lib/python3.11/site-packages/starlette/middleware/base.py", line 184, in __call__
    |     response = await self.dispatch_func(request, call_next)
    |                ^^^^^^^^^^^^^^^^^^^^^^^^^^^^^^^^^^^^^^^^^^^^
    |   File "/home/sjiang/devlocal/jnet-site/services/api-service/app/middleware/auth.py", line 30, in dispatch
    |     raise HTTPException(status_code=401, detail="Invalid API key")
    | fastapi.exceptions.HTTPException: 401: Invalid API key
    +------------------------------------

During handling of the above exception, another exception occurred:

Traceback (most recent call last):
  File "/home/sjiang/devlocal/jnet-site/services/api-service/.venv/lib/python3.11/site-packages/uvicorn/protocols/http/h11_impl.py", line 403, in run_asgi
    result = await app(  # type: ignore[func-returns-value]
             ^^^^^^^^^^^^^^^^^^^^^^^^^^^^^^^^^^^^^^^^^^^^^^
  File "/home/sjiang/devlocal/jnet-site/services/api-service/.venv/lib/python3.11/site-packages/uvicorn/middleware/proxy_headers.py", line 60, in __call__
    return await self.app(scope, receive, send)
           ^^^^^^^^^^^^^^^^^^^^^^^^^^^^^^^^^^^^
  File "/home/sjiang/devlocal/jnet-site/services/api-service/.venv/lib/python3.11/site-packages/fastapi/applications.py", line 1054, in __call__
    await super().__call__(scope, receive, send)
  File "/home/sjiang/devlocal/jnet-site/services/api-service/.venv/lib/python3.11/site-packages/starlette/applications.py", line 113, in __call__
    await self.middleware_stack(scope, receive, send)
  File "/home/sjiang/devlocal/jnet-site/services/api-service/.venv/lib/python3.11/site-packages/starlette/middleware/errors.py", line 186, in __call__
    raise exc
  File "/home/sjiang/devlocal/jnet-site/services/api-service/.venv/lib/python3.11/site-packages/starlette/middleware/errors.py", line 164, in __call__
    await self.app(scope, receive, _send)
  File "/home/sjiang/devlocal/jnet-site/services/api-service/.venv/lib/python3.11/site-packages/starlette/middleware/base.py", line 182, in __call__
    with recv_stream, send_stream, collapse_excgroups():
  File "/home/sjiang/.local/share/uv/python/cpython-3.11.13-linux-x86_64-gnu/lib/python3.11/contextlib.py", line 158, in __exit__
    self.gen.throw(typ, value, traceback)
  File "/home/sjiang/devlocal/jnet-site/services/api-service/.venv/lib/python3.11/site-packages/starlette/_utils.py", line 85, in collapse_excgroups
    raise exc
  File "/home/sjiang/devlocal/jnet-site/services/api-service/.venv/lib/python3.11/site-packages/starlette/middleware/base.py", line 184, in __call__
    response = await self.dispatch_func(request, call_next)
               ^^^^^^^^^^^^^^^^^^^^^^^^^^^^^^^^^^^^^^^^^^^^
  File "/home/sjiang/devlocal/jnet-site/services/api-service/app/middleware/auth.py", line 30, in dispatch
    raise HTTPException(status_code=401, detail="Invalid API key")
fastapi.exceptions.HTTPException: 401: Invalid API key
WARNING:app.middleware.auth:Invalid API key attempt from 127.0.0.1
INFO:     127.0.0.1:52128 - "GET /api/v1/symbols/list HTTP/1.1" 500 Internal Server Error
ERROR:    Exception in ASGI application
  + Exception Group Traceback (most recent call last):
  |   File "/home/sjiang/devlocal/jnet-site/services/api-service/.venv/lib/python3.11/site-packages/starlette/_utils.py", line 79, in collapse_excgroups
  |     yield
  |   File "/home/sjiang/devlocal/jnet-site/services/api-service/.venv/lib/python3.11/site-packages/starlette/middleware/base.py", line 183, in __call__
  |     async with anyio.create_task_group() as task_group:
  |   File "/home/sjiang/devlocal/jnet-site/services/api-service/.venv/lib/python3.11/site-packages/anyio/_backends/_asyncio.py", line 772, in __aexit__
  |     raise BaseExceptionGroup(
  | ExceptionGroup: unhandled errors in a TaskGroup (1 sub-exception)
  +-+---------------- 1 ----------------
    | Traceback (most recent call last):
    |   File "/home/sjiang/devlocal/jnet-site/services/api-service/.venv/lib/python3.11/site-packages/uvicorn/protocols/http/h11_impl.py", line 403, in run_asgi
    |     result = await app(  # type: ignore[func-returns-value]
    |              ^^^^^^^^^^^^^^^^^^^^^^^^^^^^^^^^^^^^^^^^^^^^^^
    |   File "/home/sjiang/devlocal/jnet-site/services/api-service/.venv/lib/python3.11/site-packages/uvicorn/middleware/proxy_headers.py", line 60, in __call__
    |     return await self.app(scope, receive, send)
    |            ^^^^^^^^^^^^^^^^^^^^^^^^^^^^^^^^^^^^
    |   File "/home/sjiang/devlocal/jnet-site/services/api-service/.venv/lib/python3.11/site-packages/fastapi/applications.py", line 1054, in __call__
    |     await super().__call__(scope, receive, send)
    |   File "/home/sjiang/devlocal/jnet-site/services/api-service/.venv/lib/python3.11/site-packages/starlette/applications.py", line 113, in __call__
    |     await self.middleware_stack(scope, receive, send)
    |   File "/home/sjiang/devlocal/jnet-site/services/api-service/.venv/lib/python3.11/site-packages/starlette/middleware/errors.py", line 186, in __call__
    |     raise exc
    |   File "/home/sjiang/devlocal/jnet-site/services/api-service/.venv/lib/python3.11/site-packages/starlette/middleware/errors.py", line 164, in __call__
    |     await self.app(scope, receive, _send)
    |   File "/home/sjiang/devlocal/jnet-site/services/api-service/.venv/lib/python3.11/site-packages/starlette/middleware/base.py", line 182, in __call__
    |     with recv_stream, send_stream, collapse_excgroups():
    |   File "/home/sjiang/.local/share/uv/python/cpython-3.11.13-linux-x86_64-gnu/lib/python3.11/contextlib.py", line 158, in __exit__
    |     self.gen.throw(typ, value, traceback)
    |   File "/home/sjiang/devlocal/jnet-site/services/api-service/.venv/lib/python3.11/site-packages/starlette/_utils.py", line 85, in collapse_excgroups
    |     raise exc
    |   File "/home/sjiang/devlocal/jnet-site/services/api-service/.venv/lib/python3.11/site-packages/starlette/middleware/base.py", line 184, in __call__
    |     response = await self.dispatch_func(request, call_next)
    |                ^^^^^^^^^^^^^^^^^^^^^^^^^^^^^^^^^^^^^^^^^^^^
    |   File "/home/sjiang/devlocal/jnet-site/services/api-service/app/middleware/auth.py", line 30, in dispatch
    |     raise HTTPException(status_code=401, detail="Invalid API key")
    | fastapi.exceptions.HTTPException: 401: Invalid API key
    +------------------------------------

During handling of the above exception, another exception occurred:

Traceback (most recent call last):
  File "/home/sjiang/devlocal/jnet-site/services/api-service/.venv/lib/python3.11/site-packages/uvicorn/protocols/http/h11_impl.py", line 403, in run_asgi
    result = await app(  # type: ignore[func-returns-value]
             ^^^^^^^^^^^^^^^^^^^^^^^^^^^^^^^^^^^^^^^^^^^^^^
  File "/home/sjiang/devlocal/jnet-site/services/api-service/.venv/lib/python3.11/site-packages/uvicorn/middleware/proxy_headers.py", line 60, in __call__
    return await self.app(scope, receive, send)
           ^^^^^^^^^^^^^^^^^^^^^^^^^^^^^^^^^^^^
  File "/home/sjiang/devlocal/jnet-site/services/api-service/.venv/lib/python3.11/site-packages/fastapi/applications.py", line 1054, in __call__
    await super().__call__(scope, receive, send)
  File "/home/sjiang/devlocal/jnet-site/services/api-service/.venv/lib/python3.11/site-packages/starlette/applications.py", line 113, in __call__
    await self.middleware_stack(scope, receive, send)
  File "/home/sjiang/devlocal/jnet-site/services/api-service/.venv/lib/python3.11/site-packages/starlette/middleware/errors.py", line 186, in __call__
    raise exc
  File "/home/sjiang/devlocal/jnet-site/services/api-service/.venv/lib/python3.11/site-packages/starlette/middleware/errors.py", line 164, in __call__
    await self.app(scope, receive, _send)
  File "/home/sjiang/devlocal/jnet-site/services/api-service/.venv/lib/python3.11/site-packages/starlette/middleware/base.py", line 182, in __call__
    with recv_stream, send_stream, collapse_excgroups():
  File "/home/sjiang/.local/share/uv/python/cpython-3.11.13-linux-x86_64-gnu/lib/python3.11/contextlib.py", line 158, in __exit__
    self.gen.throw(typ, value, traceback)
  File "/home/sjiang/devlocal/jnet-site/services/api-service/.venv/lib/python3.11/site-packages/starlette/_utils.py", line 85, in collapse_excgroups
    raise exc
  File "/home/sjiang/devlocal/jnet-site/services/api-service/.venv/lib/python3.11/site-packages/starlette/middleware/base.py", line 184, in __call__
    response = await self.dispatch_func(request, call_next)
               ^^^^^^^^^^^^^^^^^^^^^^^^^^^^^^^^^^^^^^^^^^^^
  File "/home/sjiang/devlocal/jnet-site/services/api-service/app/middleware/auth.py", line 30, in dispatch
    raise HTTPException(status_code=401, detail="Invalid API key")
fastapi.exceptions.HTTPException: 401: Invalid API key
WARNING:app.middleware.auth:Invalid API key attempt from 127.0.0.1
INFO:     127.0.0.1:52138 - "GET /api/v1/symbols/list HTTP/1.1" 500 Internal Server Error
ERROR:    Exception in ASGI application
  + Exception Group Traceback (most recent call last):
  |   File "/home/sjiang/devlocal/jnet-site/services/api-service/.venv/lib/python3.11/site-packages/starlette/_utils.py", line 79, in collapse_excgroups
  |     yield
  |   File "/home/sjiang/devlocal/jnet-site/services/api-service/.venv/lib/python3.11/site-packages/starlette/middleware/base.py", line 183, in __call__
  |     async with anyio.create_task_group() as task_group:
  |   File "/home/sjiang/devlocal/jnet-site/services/api-service/.venv/lib/python3.11/site-packages/anyio/_backends/_asyncio.py", line 772, in __aexit__
  |     raise BaseExceptionGroup(
  | ExceptionGroup: unhandled errors in a TaskGroup (1 sub-exception)
  +-+---------------- 1 ----------------
    | Traceback (most recent call last):
    |   File "/home/sjiang/devlocal/jnet-site/services/api-service/.venv/lib/python3.11/site-packages/uvicorn/protocols/http/h11_impl.py", line 403, in run_asgi
    |     result = await app(  # type: ignore[func-returns-value]
    |              ^^^^^^^^^^^^^^^^^^^^^^^^^^^^^^^^^^^^^^^^^^^^^^
    |   File "/home/sjiang/devlocal/jnet-site/services/api-service/.venv/lib/python3.11/site-packages/uvicorn/middleware/proxy_headers.py", line 60, in __call__
    |     return await self.app(scope, receive, send)
    |            ^^^^^^^^^^^^^^^^^^^^^^^^^^^^^^^^^^^^
    |   File "/home/sjiang/devlocal/jnet-site/services/api-service/.venv/lib/python3.11/site-packages/fastapi/applications.py", line 1054, in __call__
    |     await super().__call__(scope, receive, send)
    |   File "/home/sjiang/devlocal/jnet-site/services/api-service/.venv/lib/python3.11/site-packages/starlette/applications.py", line 113, in __call__
    |     await self.middleware_stack(scope, receive, send)
    |   File "/home/sjiang/devlocal/jnet-site/services/api-service/.venv/lib/python3.11/site-packages/starlette/middleware/errors.py", line 186, in __call__
    |     raise exc
    |   File "/home/sjiang/devlocal/jnet-site/services/api-service/.venv/lib/python3.11/site-packages/starlette/middleware/errors.py", line 164, in __call__
    |     await self.app(scope, receive, _send)
    |   File "/home/sjiang/devlocal/jnet-site/services/api-service/.venv/lib/python3.11/site-packages/starlette/middleware/base.py", line 182, in __call__
    |     with recv_stream, send_stream, collapse_excgroups():
    |   File "/home/sjiang/.local/share/uv/python/cpython-3.11.13-linux-x86_64-gnu/lib/python3.11/contextlib.py", line 158, in __exit__
    |     self.gen.throw(typ, value, traceback)
    |   File "/home/sjiang/devlocal/jnet-site/services/api-service/.venv/lib/python3.11/site-packages/starlette/_utils.py", line 85, in collapse_excgroups
    |     raise exc
    |   File "/home/sjiang/devlocal/jnet-site/services/api-service/.venv/lib/python3.11/site-packages/starlette/middleware/base.py", line 184, in __call__
    |     response = await self.dispatch_func(request, call_next)
    |                ^^^^^^^^^^^^^^^^^^^^^^^^^^^^^^^^^^^^^^^^^^^^
    |   File "/home/sjiang/devlocal/jnet-site/services/api-service/app/middleware/auth.py", line 30, in dispatch
    |     raise HTTPException(status_code=401, detail="Invalid API key")
    | fastapi.exceptions.HTTPException: 401: Invalid API key
    +------------------------------------

During handling of the above exception, another exception occurred:

Traceback (most recent call last):
  File "/home/sjiang/devlocal/jnet-site/services/api-service/.venv/lib/python3.11/site-packages/uvicorn/protocols/http/h11_impl.py", line 403, in run_asgi
    result = await app(  # type: ignore[func-returns-value]
             ^^^^^^^^^^^^^^^^^^^^^^^^^^^^^^^^^^^^^^^^^^^^^^
  File "/home/sjiang/devlocal/jnet-site/services/api-service/.venv/lib/python3.11/site-packages/uvicorn/middleware/proxy_headers.py", line 60, in __call__
    return await self.app(scope, receive, send)
           ^^^^^^^^^^^^^^^^^^^^^^^^^^^^^^^^^^^^
  File "/home/sjiang/devlocal/jnet-site/services/api-service/.venv/lib/python3.11/site-packages/fastapi/applications.py", line 1054, in __call__
    await super().__call__(scope, receive, send)
  File "/home/sjiang/devlocal/jnet-site/services/api-service/.venv/lib/python3.11/site-packages/starlette/applications.py", line 113, in __call__
    await self.middleware_stack(scope, receive, send)
  File "/home/sjiang/devlocal/jnet-site/services/api-service/.venv/lib/python3.11/site-packages/starlette/middleware/errors.py", line 186, in __call__
    raise exc
  File "/home/sjiang/devlocal/jnet-site/services/api-service/.venv/lib/python3.11/site-packages/starlette/middleware/errors.py", line 164, in __call__
    await self.app(scope, receive, _send)
  File "/home/sjiang/devlocal/jnet-site/services/api-service/.venv/lib/python3.11/site-packages/starlette/middleware/base.py", line 182, in __call__
    with recv_stream, send_stream, collapse_excgroups():
  File "/home/sjiang/.local/share/uv/python/cpython-3.11.13-linux-x86_64-gnu/lib/python3.11/contextlib.py", line 158, in __exit__
    self.gen.throw(typ, value, traceback)
  File "/home/sjiang/devlocal/jnet-site/services/api-service/.venv/lib/python3.11/site-packages/starlette/_utils.py", line 85, in collapse_excgroups
    raise exc
  File "/home/sjiang/devlocal/jnet-site/services/api-service/.venv/lib/python3.11/site-packages/starlette/middleware/base.py", line 184, in __call__
    response = await self.dispatch_func(request, call_next)
               ^^^^^^^^^^^^^^^^^^^^^^^^^^^^^^^^^^^^^^^^^^^^
  File "/home/sjiang/devlocal/jnet-site/services/api-service/app/middleware/auth.py", line 30, in dispatch
    raise HTTPException(status_code=401, detail="Invalid API key")
fastapi.exceptions.HTTPException: 401: Invalid API key
WARNING:app.middleware.auth:Invalid API key attempt from 127.0.0.1
INFO:     127.0.0.1:52150 - "GET /api/v1/symbols/list HTTP/1.1" 500 Internal Server Error
ERROR:    Exception in ASGI application
  + Exception Group Traceback (most recent call last):
  |   File "/home/sjiang/devlocal/jnet-site/services/api-service/.venv/lib/python3.11/site-packages/starlette/_utils.py", line 79, in collapse_excgroups
  |     yield
  |   File "/home/sjiang/devlocal/jnet-site/services/api-service/.venv/lib/python3.11/site-packages/starlette/middleware/base.py", line 183, in __call__
  |     async with anyio.create_task_group() as task_group:
  |   File "/home/sjiang/devlocal/jnet-site/services/api-service/.venv/lib/python3.11/site-packages/anyio/_backends/_asyncio.py", line 772, in __aexit__
  |     raise BaseExceptionGroup(
  | ExceptionGroup: unhandled errors in a TaskGroup (1 sub-exception)
  +-+---------------- 1 ----------------
    | Traceback (most recent call last):
    |   File "/home/sjiang/devlocal/jnet-site/services/api-service/.venv/lib/python3.11/site-packages/uvicorn/protocols/http/h11_impl.py", line 403, in run_asgi
    |     result = await app(  # type: ignore[func-returns-value]
    |              ^^^^^^^^^^^^^^^^^^^^^^^^^^^^^^^^^^^^^^^^^^^^^^
    |   File "/home/sjiang/devlocal/jnet-site/services/api-service/.venv/lib/python3.11/site-packages/uvicorn/middleware/proxy_headers.py", line 60, in __call__
    |     return await self.app(scope, receive, send)
    |            ^^^^^^^^^^^^^^^^^^^^^^^^^^^^^^^^^^^^
    |   File "/home/sjiang/devlocal/jnet-site/services/api-service/.venv/lib/python3.11/site-packages/fastapi/applications.py", line 1054, in __call__
    |     await super().__call__(scope, receive, send)
    |   File "/home/sjiang/devlocal/jnet-site/services/api-service/.venv/lib/python3.11/site-packages/starlette/applications.py", line 113, in __call__
    |     await self.middleware_stack(scope, receive, send)
    |   File "/home/sjiang/devlocal/jnet-site/services/api-service/.venv/lib/python3.11/site-packages/starlette/middleware/errors.py", line 186, in __call__
    |     raise exc
    |   File "/home/sjiang/devlocal/jnet-site/services/api-service/.venv/lib/python3.11/site-packages/starlette/middleware/errors.py", line 164, in __call__
    |     await self.app(scope, receive, _send)
    |   File "/home/sjiang/devlocal/jnet-site/services/api-service/.venv/lib/python3.11/site-packages/starlette/middleware/base.py", line 182, in __call__
    |     with recv_stream, send_stream, collapse_excgroups():
    |   File "/home/sjiang/.local/share/uv/python/cpython-3.11.13-linux-x86_64-gnu/lib/python3.11/contextlib.py", line 158, in __exit__
    |     self.gen.throw(typ, value, traceback)
    |   File "/home/sjiang/devlocal/jnet-site/services/api-service/.venv/lib/python3.11/site-packages/starlette/_utils.py", line 85, in collapse_excgroups
    |     raise exc
    |   File "/home/sjiang/devlocal/jnet-site/services/api-service/.venv/lib/python3.11/site-packages/starlette/middleware/base.py", line 184, in __call__
    |     response = await self.dispatch_func(request, call_next)
    |                ^^^^^^^^^^^^^^^^^^^^^^^^^^^^^^^^^^^^^^^^^^^^
    |   File "/home/sjiang/devlocal/jnet-site/services/api-service/app/middleware/auth.py", line 30, in dispatch
    |     raise HTTPException(status_code=401, detail="Invalid API key")
    | fastapi.exceptions.HTTPException: 401: Invalid API key
    +------------------------------------

During handling of the above exception, another exception occurred:

Traceback (most recent call last):
  File "/home/sjiang/devlocal/jnet-site/services/api-service/.venv/lib/python3.11/site-packages/uvicorn/protocols/http/h11_impl.py", line 403, in run_asgi
    result = await app(  # type: ignore[func-returns-value]
             ^^^^^^^^^^^^^^^^^^^^^^^^^^^^^^^^^^^^^^^^^^^^^^
  File "/home/sjiang/devlocal/jnet-site/services/api-service/.venv/lib/python3.11/site-packages/uvicorn/middleware/proxy_headers.py", line 60, in __call__
    return await self.app(scope, receive, send)
           ^^^^^^^^^^^^^^^^^^^^^^^^^^^^^^^^^^^^
  File "/home/sjiang/devlocal/jnet-site/services/api-service/.venv/lib/python3.11/site-packages/fastapi/applications.py", line 1054, in __call__
    await super().__call__(scope, receive, send)
  File "/home/sjiang/devlocal/jnet-site/services/api-service/.venv/lib/python3.11/site-packages/starlette/applications.py", line 113, in __call__
    await self.middleware_stack(scope, receive, send)
  File "/home/sjiang/devlocal/jnet-site/services/api-service/.venv/lib/python3.11/site-packages/starlette/middleware/errors.py", line 186, in __call__
    raise exc
  File "/home/sjiang/devlocal/jnet-site/services/api-service/.venv/lib/python3.11/site-packages/starlette/middleware/errors.py", line 164, in __call__
    await self.app(scope, receive, _send)
  File "/home/sjiang/devlocal/jnet-site/services/api-service/.venv/lib/python3.11/site-packages/starlette/middleware/base.py", line 182, in __call__
    with recv_stream, send_stream, collapse_excgroups():
  File "/home/sjiang/.local/share/uv/python/cpython-3.11.13-linux-x86_64-gnu/lib/python3.11/contextlib.py", line 158, in __exit__
    self.gen.throw(typ, value, traceback)
  File "/home/sjiang/devlocal/jnet-site/services/api-service/.venv/lib/python3.11/site-packages/starlette/_utils.py", line 85, in collapse_excgroups
    raise exc
  File "/home/sjiang/devlocal/jnet-site/services/api-service/.venv/lib/python3.11/site-packages/starlette/middleware/base.py", line 184, in __call__
    response = await self.dispatch_func(request, call_next)
               ^^^^^^^^^^^^^^^^^^^^^^^^^^^^^^^^^^^^^^^^^^^^
  File "/home/sjiang/devlocal/jnet-site/services/api-service/app/middleware/auth.py", line 30, in dispatch
    raise HTTPException(status_code=401, detail="Invalid API key")
fastapi.exceptions.HTTPException: 401: Invalid API key
WARNING:  StatReload detected changes in 'app/middleware/auth.py'. Reloading...
INFO:     Shutting down
INFO:     Waiting for application shutdown.
INFO:app.main:Shutting down API Service
INFO:     Application shutdown complete.
INFO:     Finished server process [165241]
INFO:     Started server process [174075]
INFO:     Waiting for application startup.
INFO:app.main:Starting API Service in development mode
INFO:     Application startup complete.
WARNING:  StatReload detected changes in 'app/middleware/auth.py'. Reloading...
INFO:     Shutting down
INFO:     Waiting for application shutdown.
INFO:app.main:Shutting down API Service
INFO:     Application shutdown complete.
INFO:     Finished server process [174075]
INFO:     Started server process [174107]
INFO:     Waiting for application startup.
INFO:app.main:Starting API Service in development mode
INFO:     Application startup complete.
WARNING:app.middleware.auth:Invalid API key attempt from 127.0.0.1
INFO:     127.0.0.1:44470 - "GET /api/v1/symbols/list HTTP/1.1" 401 Unauthorized
INFO:httpx:HTTP Request: GET http://localhost:9000/api/v1/list "HTTP/1.1 200 OK"
INFO:     127.0.0.1:52826 - "GET /api/v1/symbols/list HTTP/1.1" 200 OK
WARNING:app.middleware.auth:Invalid API key attempt from 127.0.0.1
INFO:     127.0.0.1:55074 - "GET /api/v1/symbols/list HTTP/1.1" 401 Unauthorized
WARNING:app.middleware.auth:Invalid API key attempt from 127.0.0.1
INFO:     127.0.0.1:55074 - "GET /api/v1/symbols/list HTTP/1.1" 401 Unauthorized
WARNING:app.middleware.auth:Invalid API key attempt from 127.0.0.1
INFO:     127.0.0.1:55078 - "GET /api/v1/symbols/list HTTP/1.1" 401 Unauthorized
WARNING:app.middleware.auth:Invalid API key attempt from 127.0.0.1
INFO:     127.0.0.1:41186 - "GET /api/v1/symbols/list HTTP/1.1" 401 Unauthorized
WARNING:app.middleware.auth:Invalid API key attempt from 127.0.0.1
INFO:     127.0.0.1:41186 - "GET /api/v1/symbols/list HTTP/1.1" 401 Unauthorized
WARNING:app.middleware.auth:Invalid API key attempt from 127.0.0.1
INFO:     127.0.0.1:41186 - "GET /api/v1/symbols/list HTTP/1.1" 401 Unauthorized
WARNING:app.middleware.auth:Invalid API key attempt from 127.0.0.1
INFO:     127.0.0.1:35708 - "GET /api/v1/symbols/list HTTP/1.1" 401 Unauthorized
WARNING:app.middleware.auth:Invalid API key attempt from 127.0.0.1
INFO:     127.0.0.1:35708 - "GET /api/v1/symbols/list HTTP/1.1" 401 Unauthorized
WARNING:app.middleware.auth:Invalid API key attempt from 127.0.0.1
INFO:     127.0.0.1:35720 - "GET /api/v1/symbols/list HTTP/1.1" 401 Unauthorized
WARNING:  StatReload detected changes in 'app/main.py'. Reloading...
INFO:     Shutting down
INFO:     Waiting for application shutdown.
INFO:app.main:Shutting down API Service
INFO:     Application shutdown complete.
INFO:     Finished server process [174107]
INFO:     Started server process [176155]
INFO:     Waiting for application startup.
INFO:app.main:Starting API Service in development mode
INFO:     Application startup complete.
WARNING:  StatReload detected changes in 'app/main.py'. Reloading...
INFO:     Shutting down
INFO:     Waiting for application shutdown.
INFO:app.main:Shutting down API Service
INFO:     Application shutdown complete.
INFO:     Finished server process [176155]
INFO:     Started server process [176674]
INFO:     Waiting for application startup.
INFO:app.main:Starting API Service in development mode
INFO:     Application startup complete.
INFO:httpx:HTTP Request: GET http://localhost:9000/api/v1/list "HTTP/1.1 200 OK"
INFO:     127.0.0.1:57394 - "GET /api/v1/symbols/list HTTP/1.1" 200 OK
WARNING:app.middleware.auth:Invalid API key attempt from 127.0.0.1
INFO:     127.0.0.1:37304 - "GET /api/v1/symbols/list HTTP/1.1" 401 Unauthorized
WARNING:app.middleware.auth:Invalid API key attempt from 127.0.0.1
INFO:     127.0.0.1:37304 - "GET /api/v1/symbols/list HTTP/1.1" 401 Unauthorized
WARNING:app.middleware.auth:Invalid API key attempt from 127.0.0.1
INFO:     127.0.0.1:37318 - "GET /api/v1/symbols/list HTTP/1.1" 401 Unauthorized
WARNING:app.middleware.auth:Invalid API key attempt from 127.0.0.1
INFO:     127.0.0.1:37160 - "GET /api/v1/symbols/list HTTP/1.1" 401 Unauthorized
WARNING:app.middleware.auth:Invalid API key attempt from 127.0.0.1
INFO:     127.0.0.1:37160 - "GET /api/v1/symbols/list HTTP/1.1" 401 Unauthorized
WARNING:app.middleware.auth:Invalid API key attempt from 127.0.0.1
INFO:     127.0.0.1:37170 - "GET /api/v1/symbols/list HTTP/1.1" 401 Unauthorized
WARNING:app.middleware.auth:Invalid API key attempt from 127.0.0.1
INFO:     127.0.0.1:56336 - "GET /api/v1/symbols/list HTTP/1.1" 401 Unauthorized
WARNING:app.middleware.auth:Invalid API key attempt from 127.0.0.1
INFO:     127.0.0.1:56336 - "GET /api/v1/symbols/list HTTP/1.1" 401 Unauthorized
WARNING:app.middleware.auth:Invalid API key attempt from 127.0.0.1
INFO:     127.0.0.1:56344 - "GET /api/v1/symbols/list HTTP/1.1" 401 Unauthorized
WARNING:app.middleware.auth:Invalid API key attempt from 127.0.0.1
INFO:     127.0.0.1:57180 - "OPTIONS /api/v1/symbols/list HTTP/1.1" 401 Unauthorized
WARNING:  StatReload detected changes in 'app/middleware/auth.py'. Reloading...
INFO:     Shutting down
INFO:     Waiting for application shutdown.
INFO:app.main:Shutting down API Service
INFO:     Application shutdown complete.
INFO:     Finished server process [176674]
INFO:     Started server process [178086]
INFO:     Waiting for application startup.
INFO:app.main:Starting API Service in development mode
INFO:     Application startup complete.
WARNING:app.middleware.auth:Invalid API key attempt from 127.0.0.1
INFO:     127.0.0.1:44326 - "GET /api/v1/symbols/list HTTP/1.1" 401 Unauthorized
WARNING:app.middleware.auth:Invalid API key attempt from 127.0.0.1
INFO:     127.0.0.1:44326 - "GET /api/v1/symbols/list HTTP/1.1" 401 Unauthorized
WARNING:app.middleware.auth:Invalid API key attempt from 127.0.0.1
INFO:     127.0.0.1:44336 - "GET /api/v1/symbols/list HTTP/1.1" 401 Unauthorized
WARNING:app.middleware.auth:Invalid API key attempt from 127.0.0.1
INFO:     127.0.0.1:37366 - "GET /api/v1/symbols/list HTTP/1.1" 401 Unauthorized
WARNING:app.middleware.auth:Invalid API key attempt from 127.0.0.1
INFO:     127.0.0.1:37366 - "GET /api/v1/symbols/list HTTP/1.1" 401 Unauthorized
WARNING:app.middleware.auth:Invalid API key attempt from 127.0.0.1
INFO:     127.0.0.1:37376 - "GET /api/v1/symbols/list HTTP/1.1" 401 Unauthorized
WARNING:app.middleware.auth:Invalid API key attempt from 127.0.0.1
INFO:     127.0.0.1:59506 - "GET /api/v1/symbols/list HTTP/1.1" 401 Unauthorized
WARNING:app.middleware.auth:Invalid API key attempt from 127.0.0.1
INFO:     127.0.0.1:59506 - "GET /api/v1/symbols/list HTTP/1.1" 401 Unauthorized
WARNING:app.middleware.auth:Invalid API key attempt from 127.0.0.1
INFO:     127.0.0.1:59520 - "GET /api/v1/symbols/list HTTP/1.1" 401 Unauthorized
INFO:httpx:HTTP Request: GET http://localhost:9000/api/v1/list "HTTP/1.1 200 OK"
INFO:     127.0.0.1:40360 - "GET /api/v1/symbols/list HTTP/1.1" 200 OK
WARNING:app.middleware.auth:Invalid API key attempt from 127.0.0.1
INFO:     127.0.0.1:60202 - "GET /api/v1/symbols/list HTTP/1.1" 401 Unauthorized
WARNING:app.middleware.auth:Invalid API key attempt from 127.0.0.1
INFO:     127.0.0.1:60202 - "GET /api/v1/symbols/list HTTP/1.1" 401 Unauthorized
WARNING:app.middleware.auth:Invalid API key attempt from 127.0.0.1
INFO:     127.0.0.1:60202 - "GET /api/v1/symbols/list HTTP/1.1" 401 Unauthorized
WARNING:app.middleware.auth:Invalid API key attempt from 127.0.0.1
INFO:     127.0.0.1:60206 - "GET /api/v1/symbols/list HTTP/1.1" 401 Unauthorized
WARNING:app.middleware.auth:Invalid API key attempt from 127.0.0.1
INFO:     127.0.0.1:60206 - "GET /api/v1/symbols/list HTTP/1.1" 401 Unauthorized
WARNING:app.middleware.auth:Invalid API key attempt from 127.0.0.1
INFO:     127.0.0.1:58302 - "GET /api/v1/symbols/list HTTP/1.1" 401 Unauthorized
WARNING:  StatReload detected changes in 'app/main.py'. Reloading...
INFO:     Shutting down
INFO:     Waiting for application shutdown.
INFO:app.main:Shutting down API Service
INFO:     Application shutdown complete.
INFO:     Finished server process [178086]
INFO:     Started server process [183764]
INFO:     Waiting for application startup.
INFO:app.main:Starting API Service in development mode
INFO:     Application startup complete.
INFO:httpx:HTTP Request: GET http://localhost:9000/api/v1/list "HTTP/1.1 200 OK"
INFO:     127.0.0.1:40576 - "GET /api/v1/symbols/list HTTP/1.1" 200 OK
INFO:httpx:HTTP Request: GET http://localhost:9000/api/v1/list "HTTP/1.1 200 OK"
INFO:     127.0.0.1:40576 - "GET /api/v1/symbols/list HTTP/1.1" 200 OK
INFO:httpx:HTTP Request: GET http://localhost:9000/api/v1/list "HTTP/1.1 200 OK"
INFO:     127.0.0.1:40586 - "GET /api/v1/symbols/list HTTP/1.1" 200 OK
WARNING:  StatReload detected changes in 'app/config.py'. Reloading...
INFO:     Shutting down
INFO:     Waiting for application shutdown.
INFO:app.main:Shutting down API Service
INFO:     Application shutdown complete.
INFO:     Finished server process [183764]
INFO:     Started server process [183919]
INFO:     Waiting for application startup.
INFO:app.main:Starting API Service in development mode
INFO:     Application startup complete.
WARNING:  StatReload detected changes in 'app/main.py'. Reloading...
INFO:     Shutting down
INFO:     Waiting for application shutdown.
INFO:app.main:Shutting down API Service
INFO:     Application shutdown complete.
INFO:     Finished server process [183919]
INFO:     Started server process [183954]
INFO:     Waiting for application startup.
INFO:app.main:Starting API Service in development mode
INFO:     Application startup complete.
WARNING:app.middleware.auth:Invalid API key attempt from 127.0.0.1
INFO:     127.0.0.1:56956 - "GET /api/v1/symbols/list HTTP/1.1" 401 Unauthorized
WARNING:app.middleware.auth:Invalid API key attempt from 127.0.0.1
INFO:     127.0.0.1:56956 - "GET /api/v1/symbols/list HTTP/1.1" 401 Unauthorized
WARNING:app.middleware.auth:Invalid API key attempt from 127.0.0.1
INFO:     127.0.0.1:56958 - "GET /api/v1/symbols/list HTTP/1.1" 401 Unauthorized
WARNING:app.middleware.auth:Invalid API key attempt from 127.0.0.1
INFO:     127.0.0.1:38042 - "GET /api/v1/symbols/list HTTP/1.1" 401 Unauthorized
WARNING:app.middleware.auth:Invalid API key attempt from 127.0.0.1
INFO:     127.0.0.1:38042 - "GET /api/v1/symbols/list HTTP/1.1" 401 Unauthorized
WARNING:app.middleware.auth:Invalid API key attempt from 127.0.0.1
INFO:     127.0.0.1:38056 - "GET /api/v1/symbols/list HTTP/1.1" 401 Unauthorized
INFO:     127.0.0.1:35122 - "GET /symbols HTTP/1.1" 404 Not Found
INFO:     127.0.0.1:45034 - "GET /api/v1/symbols HTTP/1.1" 404 Not Found
INFO:     127.0.0.1:45040 - "GET /docs HTTP/1.1" 200 OK
WARNING:app.middleware.auth:Invalid API key attempt from 127.0.0.1
INFO:     127.0.0.1:57096 - "GET /api/v1/symbols HTTP/1.1" 401 Unauthorized
INFO:     Shutting down
INFO:     Waiting for application shutdown.
INFO:app.main:Shutting down API Service
INFO:     Application shutdown complete.
INFO:     Finished server process [183954]
INFO:     Stopping reloader process [165239]
